[2025-07-26T07:58:28.236+0700] {local_task_job_runner.py:120} INFO - ::group::Pre task execution logs
[2025-07-26T07:58:29.209+0700] {taskinstance.py:2076} INFO - Dependencies all met for dep_context=non-requeueable deps ti=<TaskInstance: etl_local_postgres_pipeline.load_user_dim_table scheduled__2025-07-26T00:00:00+00:00 [queued]>
[2025-07-26T07:58:29.465+0700] {taskinstance.py:2076} INFO - Dependencies all met for dep_context=requeueable deps ti=<TaskInstance: etl_local_postgres_pipeline.load_user_dim_table scheduled__2025-07-26T00:00:00+00:00 [queued]>
[2025-07-26T07:58:29.465+0700] {taskinstance.py:2306} INFO - Starting attempt 5 of 8
[2025-07-26T07:58:29.916+0700] {taskinstance.py:2330} INFO - Executing <Task(PythonOperator): load_user_dim_table> on 2025-07-26 00:00:00+00:00
[2025-07-26T07:58:29.927+0700] {standard_task_runner.py:90} INFO - Running: ['airflow', 'tasks', 'run', 'etl_local_postgres_pipeline', 'load_user_dim_table', 'scheduled__2025-07-26T00:00:00+00:00', '--job-id', '371', '--raw', '--subdir', 'DAGS_FOLDER/etl_pipeline_pjt.py', '--cfg-path', '/tmp/tmps9qw2hqh']
[2025-07-26T07:58:29.929+0700] {standard_task_runner.py:91} INFO - Job 371: Subtask load_user_dim_table
[2025-07-26T07:58:29.929+0700] {logging_mixin.py:188} WARNING - /home/ngtph/airflow/airflow_venv/lib/python3.12/site-packages/airflow/task/task_runner/standard_task_runner.py:61 DeprecationWarning: This process (pid=5335) is multi-threaded, use of fork() may lead to deadlocks in the child.
[2025-07-26T07:58:29.930+0700] {standard_task_runner.py:63} INFO - Started process 5340 to run task
[2025-07-26T07:58:35.286+0700] {task_command.py:426} INFO - Running <TaskInstance: etl_local_postgres_pipeline.load_user_dim_table scheduled__2025-07-26T00:00:00+00:00 [running]> on host DESKTOP-9M5T9P5.localdomain
[2025-07-26T07:58:42.470+0700] {taskinstance.py:2648} INFO - Exporting env vars: AIRFLOW_CTX_DAG_OWNER='phuongnt226' AIRFLOW_CTX_DAG_ID='etl_local_postgres_pipeline' AIRFLOW_CTX_TASK_ID='load_user_dim_table' AIRFLOW_CTX_EXECUTION_DATE='2025-07-26T00:00:00+00:00' AIRFLOW_CTX_TRY_NUMBER='5' AIRFLOW_CTX_DAG_RUN_ID='scheduled__2025-07-26T00:00:00+00:00'
[2025-07-26T07:58:42.471+0700] {taskinstance.py:430} INFO - ::endgroup::
[2025-07-26T07:58:43.675+0700] {base.py:84} INFO - Using connection ID 'postgres_id' for task execution.
[2025-07-26T07:58:44.351+0700] {sql.py:470} INFO - Running statement: 
    INSERT INTO users (userid, firstname, lastname, gender, level)
    SELECT DISTINCT userid, firstname, lastname, gender, level
    FROM staging_events
    WHERE page='NextSong'
, parameters: None
[2025-07-26T07:58:44.498+0700] {taskinstance.py:441} INFO - ::group::Post task execution logs
[2025-07-26T07:58:44.499+0700] {taskinstance.py:2905} ERROR - Task failed with exception
Traceback (most recent call last):
  File "/home/ngtph/airflow/airflow_venv/lib/python3.12/site-packages/airflow/models/taskinstance.py", line 465, in _execute_task
    result = _execute_callable(context=context, **execute_callable_kwargs)
             ^^^^^^^^^^^^^^^^^^^^^^^^^^^^^^^^^^^^^^^^^^^^^^^^^^^^^^^^^^^^^
  File "/home/ngtph/airflow/airflow_venv/lib/python3.12/site-packages/airflow/models/taskinstance.py", line 432, in _execute_callable
    return execute_callable(context=context, **execute_callable_kwargs)
           ^^^^^^^^^^^^^^^^^^^^^^^^^^^^^^^^^^^^^^^^^^^^^^^^^^^^^^^^^^^^
  File "/home/ngtph/airflow/airflow_venv/lib/python3.12/site-packages/airflow/models/baseoperator.py", line 400, in wrapper
    return func(self, *args, **kwargs)
           ^^^^^^^^^^^^^^^^^^^^^^^^^^^
  File "/home/ngtph/airflow/airflow_venv/lib/python3.12/site-packages/airflow/operators/python.py", line 235, in execute
    return_value = self.execute_callable()
                   ^^^^^^^^^^^^^^^^^^^^^^^
  File "/home/ngtph/airflow/airflow_venv/lib/python3.12/site-packages/airflow/operators/python.py", line 252, in execute_callable
    return self.python_callable(*self.op_args, **self.op_kwargs)
           ^^^^^^^^^^^^^^^^^^^^^^^^^^^^^^^^^^^^^^^^^^^^^^^^^^^^^
  File "/home/ngtph/airflow/dags/etl_pipeline_pjt.py", line 102, in load_users_table
    execute_sql(sql_queries.SqlQueries.user_table_insert)
  File "/home/ngtph/airflow/dags/etl_pipeline_pjt.py", line 17, in execute_sql
    result = hook.run(sql_statement)
             ^^^^^^^^^^^^^^^^^^^^^^^
  File "/home/ngtph/airflow/airflow_venv/lib/python3.12/site-packages/airflow/providers/common/sql/hooks/sql.py", line 418, in run
    self._run_command(cur, sql_statement, parameters)
  File "/home/ngtph/airflow/airflow_venv/lib/python3.12/site-packages/airflow/providers/common/sql/hooks/sql.py", line 475, in _run_command
    cur.execute(sql_statement)
psycopg2.errors.UndefinedColumn: column "firstname" of relation "users" does not exist
LINE 2:     INSERT INTO users (userid, firstname, lastname, gender, ...
                                       ^

[2025-07-26T07:58:45.274+0700] {taskinstance.py:1206} INFO - Marking task as UP_FOR_RETRY. dag_id=etl_local_postgres_pipeline, task_id=load_user_dim_table, run_id=scheduled__2025-07-26T00:00:00+00:00, execution_date=20250726T000000, start_date=20250726T005829, end_date=20250726T005845
[2025-07-26T07:58:45.643+0700] {standard_task_runner.py:110} ERROR - Failed to execute job 371 for task load_user_dim_table (column "firstname" of relation "users" does not exist
LINE 2:     INSERT INTO users (userid, firstname, lastname, gender, ...
                                       ^
; 5340)
[2025-07-26T07:58:45.672+0700] {local_task_job_runner.py:240} INFO - Task exited with return code 1
[2025-07-26T07:58:46.632+0700] {taskinstance.py:3498} INFO - 0 downstream tasks scheduled from follow-on schedule check
[2025-07-26T07:58:46.696+0700] {local_task_job_runner.py:222} INFO - ::endgroup::
