[2025-07-25T17:43:58.416+0700] {taskinstance.py:1956} INFO - Dependencies all met for dep_context=non-requeueable deps ti=<TaskInstance: etl_local_postgres_pipeline.stage_events manual__2025-07-25T10:05:24.508727+00:00 [queued]>
[2025-07-25T17:43:58.891+0700] {taskinstance.py:1956} INFO - Dependencies all met for dep_context=requeueable deps ti=<TaskInstance: etl_local_postgres_pipeline.stage_events manual__2025-07-25T10:05:24.508727+00:00 [queued]>
[2025-07-25T17:43:58.892+0700] {taskinstance.py:2170} INFO - Starting attempt 2 of 4
[2025-07-25T17:43:59.475+0700] {taskinstance.py:2191} INFO - Executing <Task(PythonOperator): stage_events> on 2025-07-25 10:05:24.508727+00:00
[2025-07-25T17:43:59.492+0700] {standard_task_runner.py:60} INFO - Started process 16915 to run task
[2025-07-25T17:43:59.535+0700] {standard_task_runner.py:87} INFO - Running: ['airflow', 'tasks', 'run', 'etl_local_postgres_pipeline', 'stage_events', 'manual__2025-07-25T10:05:24.508727+00:00', '--job-id', '40', '--raw', '--subdir', 'DAGS_FOLDER/etl_pipeline_pjt.py', '--cfg-path', '/tmp/tmpcm7yni6e']
[2025-07-25T17:43:59.559+0700] {standard_task_runner.py:88} INFO - Job 40: Subtask stage_events
[2025-07-25T17:44:05.183+0700] {task_command.py:423} INFO - Running <TaskInstance: etl_local_postgres_pipeline.stage_events manual__2025-07-25T10:05:24.508727+00:00 [running]> on host DESKTOP-9M5T9P5.localdomain
[2025-07-25T17:44:12.259+0700] {taskinstance.py:2480} INFO - Exporting env vars: AIRFLOW_CTX_DAG_OWNER='phuongnt226' AIRFLOW_CTX_DAG_ID='etl_local_postgres_pipeline' AIRFLOW_CTX_TASK_ID='stage_events' AIRFLOW_CTX_EXECUTION_DATE='2025-07-25T10:05:24.508727+00:00' AIRFLOW_CTX_TRY_NUMBER='2' AIRFLOW_CTX_DAG_RUN_ID='manual__2025-07-25T10:05:24.508727+00:00'
[2025-07-25T17:44:13.059+0700] {logging_mixin.py:188} INFO - Find out 30 envent files.
[2025-07-25T17:50:04.991+0700] {job.py:213} ERROR - Job heartbeat got an exception
Traceback (most recent call last):
  File "/home/ngtph/airflow/airflow_venv/lib/python3.11/site-packages/sqlalchemy/engine/base.py", line 3371, in _wrap_pool_connect
    return fn()
           ^^^^
  File "/home/ngtph/airflow/airflow_venv/lib/python3.11/site-packages/sqlalchemy/pool/base.py", line 327, in connect
    return _ConnectionFairy._checkout(self)
           ^^^^^^^^^^^^^^^^^^^^^^^^^^^^^^^^
  File "/home/ngtph/airflow/airflow_venv/lib/python3.11/site-packages/sqlalchemy/pool/base.py", line 894, in _checkout
    fairy = _ConnectionRecord.checkout(pool)
            ^^^^^^^^^^^^^^^^^^^^^^^^^^^^^^^^
  File "/home/ngtph/airflow/airflow_venv/lib/python3.11/site-packages/sqlalchemy/pool/base.py", line 493, in checkout
    rec = pool._do_get()
          ^^^^^^^^^^^^^^
  File "/home/ngtph/airflow/airflow_venv/lib/python3.11/site-packages/sqlalchemy/pool/impl.py", line 256, in _do_get
    return self._create_connection()
           ^^^^^^^^^^^^^^^^^^^^^^^^^
  File "/home/ngtph/airflow/airflow_venv/lib/python3.11/site-packages/sqlalchemy/pool/base.py", line 273, in _create_connection
    return _ConnectionRecord(self)
           ^^^^^^^^^^^^^^^^^^^^^^^
  File "/home/ngtph/airflow/airflow_venv/lib/python3.11/site-packages/sqlalchemy/pool/base.py", line 388, in __init__
    self.__connect()
  File "/home/ngtph/airflow/airflow_venv/lib/python3.11/site-packages/sqlalchemy/pool/base.py", line 690, in __connect
    with util.safe_reraise():
  File "/home/ngtph/airflow/airflow_venv/lib/python3.11/site-packages/sqlalchemy/util/langhelpers.py", line 70, in __exit__
    compat.raise_(
  File "/home/ngtph/airflow/airflow_venv/lib/python3.11/site-packages/sqlalchemy/util/compat.py", line 211, in raise_
    raise exception
  File "/home/ngtph/airflow/airflow_venv/lib/python3.11/site-packages/sqlalchemy/pool/base.py", line 686, in __connect
    self.dbapi_connection = connection = pool._invoke_creator(self)
                                         ^^^^^^^^^^^^^^^^^^^^^^^^^^
  File "/home/ngtph/airflow/airflow_venv/lib/python3.11/site-packages/sqlalchemy/engine/create.py", line 574, in connect
    return dialect.connect(*cargs, **cparams)
           ^^^^^^^^^^^^^^^^^^^^^^^^^^^^^^^^^^
  File "/home/ngtph/airflow/airflow_venv/lib/python3.11/site-packages/sqlalchemy/engine/default.py", line 598, in connect
    return self.dbapi.connect(*cargs, **cparams)
           ^^^^^^^^^^^^^^^^^^^^^^^^^^^^^^^^^^^^^
  File "/home/ngtph/airflow/airflow_venv/lib/python3.11/site-packages/psycopg2/__init__.py", line 122, in connect
    conn = _connect(dsn, connection_factory=connection_factory, **kwasync)
           ^^^^^^^^^^^^^^^^^^^^^^^^^^^^^^^^^^^^^^^^^^^^^^^^^^^^^^^^^^^^^^^
psycopg2.OperationalError: could not translate host name "dpg-d21jd8ndiees73du4i2g-a.singapore-postgres.render.com" to address: Temporary failure in name resolution


The above exception was the direct cause of the following exception:

Traceback (most recent call last):
  File "/home/ngtph/airflow/airflow_venv/lib/python3.11/site-packages/airflow/jobs/job.py", line 187, in heartbeat
    self._merge_from(Job._fetch_from_db(self, session))
                     ^^^^^^^^^^^^^^^^^^^^^^^^^^^^^^^^^
  File "/home/ngtph/airflow/airflow_venv/lib/python3.11/site-packages/airflow/api_internal/internal_api_call.py", line 114, in wrapper
    return func(*args, **kwargs)
           ^^^^^^^^^^^^^^^^^^^^^
  File "/home/ngtph/airflow/airflow_venv/lib/python3.11/site-packages/airflow/utils/session.py", line 76, in wrapper
    return func(*args, **kwargs)
           ^^^^^^^^^^^^^^^^^^^^^
  File "/home/ngtph/airflow/airflow_venv/lib/python3.11/site-packages/airflow/jobs/job.py", line 308, in _fetch_from_db
    session.merge(job)
  File "/home/ngtph/airflow/airflow_venv/lib/python3.11/site-packages/sqlalchemy/orm/session.py", line 3056, in merge
    return self._merge(
           ^^^^^^^^^^^^
  File "/home/ngtph/airflow/airflow_venv/lib/python3.11/site-packages/sqlalchemy/orm/session.py", line 3136, in _merge
    merged = self.get(
             ^^^^^^^^^
  File "/home/ngtph/airflow/airflow_venv/lib/python3.11/site-packages/sqlalchemy/orm/session.py", line 2853, in get
    return self._get_impl(
           ^^^^^^^^^^^^^^^
  File "/home/ngtph/airflow/airflow_venv/lib/python3.11/site-packages/sqlalchemy/orm/session.py", line 2975, in _get_impl
    return db_load_fn(
           ^^^^^^^^^^^
  File "/home/ngtph/airflow/airflow_venv/lib/python3.11/site-packages/sqlalchemy/orm/loading.py", line 530, in load_on_pk_identity
    session.execute(
  File "/home/ngtph/airflow/airflow_venv/lib/python3.11/site-packages/sqlalchemy/orm/session.py", line 1716, in execute
    conn = self._connection_for_bind(bind)
           ^^^^^^^^^^^^^^^^^^^^^^^^^^^^^^^
  File "/home/ngtph/airflow/airflow_venv/lib/python3.11/site-packages/sqlalchemy/orm/session.py", line 1555, in _connection_for_bind
    return self._transaction._connection_for_bind(
           ^^^^^^^^^^^^^^^^^^^^^^^^^^^^^^^^^^^^^^^
  File "/home/ngtph/airflow/airflow_venv/lib/python3.11/site-packages/sqlalchemy/orm/session.py", line 750, in _connection_for_bind
    conn = bind.connect()
           ^^^^^^^^^^^^^^
  File "/home/ngtph/airflow/airflow_venv/lib/python3.11/site-packages/sqlalchemy/future/engine.py", line 412, in connect
    return super(Engine, self).connect()
           ^^^^^^^^^^^^^^^^^^^^^^^^^^^^^
  File "/home/ngtph/airflow/airflow_venv/lib/python3.11/site-packages/sqlalchemy/engine/base.py", line 3325, in connect
    return self._connection_cls(self, close_with_result=close_with_result)
           ^^^^^^^^^^^^^^^^^^^^^^^^^^^^^^^^^^^^^^^^^^^^^^^^^^^^^^^^^^^^^^^
  File "/home/ngtph/airflow/airflow_venv/lib/python3.11/site-packages/sqlalchemy/engine/base.py", line 96, in __init__
    else engine.raw_connection()
         ^^^^^^^^^^^^^^^^^^^^^^^
  File "/home/ngtph/airflow/airflow_venv/lib/python3.11/site-packages/sqlalchemy/engine/base.py", line 3404, in raw_connection
    return self._wrap_pool_connect(self.pool.connect, _connection)
           ^^^^^^^^^^^^^^^^^^^^^^^^^^^^^^^^^^^^^^^^^^^^^^^^^^^^^^^
  File "/home/ngtph/airflow/airflow_venv/lib/python3.11/site-packages/sqlalchemy/engine/base.py", line 3374, in _wrap_pool_connect
    Connection._handle_dbapi_exception_noconnection(
  File "/home/ngtph/airflow/airflow_venv/lib/python3.11/site-packages/sqlalchemy/engine/base.py", line 2208, in _handle_dbapi_exception_noconnection
    util.raise_(
  File "/home/ngtph/airflow/airflow_venv/lib/python3.11/site-packages/sqlalchemy/util/compat.py", line 211, in raise_
    raise exception
  File "/home/ngtph/airflow/airflow_venv/lib/python3.11/site-packages/sqlalchemy/engine/base.py", line 3371, in _wrap_pool_connect
    return fn()
           ^^^^
  File "/home/ngtph/airflow/airflow_venv/lib/python3.11/site-packages/sqlalchemy/pool/base.py", line 327, in connect
    return _ConnectionFairy._checkout(self)
           ^^^^^^^^^^^^^^^^^^^^^^^^^^^^^^^^
  File "/home/ngtph/airflow/airflow_venv/lib/python3.11/site-packages/sqlalchemy/pool/base.py", line 894, in _checkout
    fairy = _ConnectionRecord.checkout(pool)
            ^^^^^^^^^^^^^^^^^^^^^^^^^^^^^^^^
  File "/home/ngtph/airflow/airflow_venv/lib/python3.11/site-packages/sqlalchemy/pool/base.py", line 493, in checkout
    rec = pool._do_get()
          ^^^^^^^^^^^^^^
  File "/home/ngtph/airflow/airflow_venv/lib/python3.11/site-packages/sqlalchemy/pool/impl.py", line 256, in _do_get
    return self._create_connection()
           ^^^^^^^^^^^^^^^^^^^^^^^^^
  File "/home/ngtph/airflow/airflow_venv/lib/python3.11/site-packages/sqlalchemy/pool/base.py", line 273, in _create_connection
    return _ConnectionRecord(self)
           ^^^^^^^^^^^^^^^^^^^^^^^
  File "/home/ngtph/airflow/airflow_venv/lib/python3.11/site-packages/sqlalchemy/pool/base.py", line 388, in __init__
    self.__connect()
  File "/home/ngtph/airflow/airflow_venv/lib/python3.11/site-packages/sqlalchemy/pool/base.py", line 690, in __connect
    with util.safe_reraise():
  File "/home/ngtph/airflow/airflow_venv/lib/python3.11/site-packages/sqlalchemy/util/langhelpers.py", line 70, in __exit__
    compat.raise_(
  File "/home/ngtph/airflow/airflow_venv/lib/python3.11/site-packages/sqlalchemy/util/compat.py", line 211, in raise_
    raise exception
  File "/home/ngtph/airflow/airflow_venv/lib/python3.11/site-packages/sqlalchemy/pool/base.py", line 686, in __connect
    self.dbapi_connection = connection = pool._invoke_creator(self)
                                         ^^^^^^^^^^^^^^^^^^^^^^^^^^
  File "/home/ngtph/airflow/airflow_venv/lib/python3.11/site-packages/sqlalchemy/engine/create.py", line 574, in connect
    return dialect.connect(*cargs, **cparams)
           ^^^^^^^^^^^^^^^^^^^^^^^^^^^^^^^^^^
  File "/home/ngtph/airflow/airflow_venv/lib/python3.11/site-packages/sqlalchemy/engine/default.py", line 598, in connect
    return self.dbapi.connect(*cargs, **cparams)
           ^^^^^^^^^^^^^^^^^^^^^^^^^^^^^^^^^^^^^
  File "/home/ngtph/airflow/airflow_venv/lib/python3.11/site-packages/psycopg2/__init__.py", line 122, in connect
    conn = _connect(dsn, connection_factory=connection_factory, **kwasync)
           ^^^^^^^^^^^^^^^^^^^^^^^^^^^^^^^^^^^^^^^^^^^^^^^^^^^^^^^^^^^^^^^
sqlalchemy.exc.OperationalError: (psycopg2.OperationalError) could not translate host name "dpg-d21jd8ndiees73du4i2g-a.singapore-postgres.render.com" to address: Temporary failure in name resolution

(Background on this error at: https://sqlalche.me/e/14/e3q8)
[2025-07-25T17:50:05.124+0700] {job.py:221} ERROR - Job heartbeat failed with error. Scheduler is in unhealthy state
[2025-07-25T17:51:15.850+0700] {job.py:221} ERROR - Job heartbeat failed with error. Scheduler is in unhealthy state
[2025-07-25T17:51:39.870+0700] {logging_mixin.py:188} INFO - Close connection to stage_events.
[2025-07-25T17:51:39.935+0700] {python.py:201} INFO - Done. Returned value was: None
[2025-07-25T17:51:41.361+0700] {taskinstance.py:1138} INFO - Marking task as SUCCESS. dag_id=etl_local_postgres_pipeline, task_id=stage_events, execution_date=20250725T100524, start_date=20250725T104358, end_date=20250725T105141
