[2025-07-26T01:29:21.744+0700] {local_task_job_runner.py:120} INFO - ::group::Pre task execution logs
[2025-07-26T01:29:22.808+0700] {taskinstance.py:2076} INFO - Dependencies all met for dep_context=non-requeueable deps ti=<TaskInstance: etl_local_postgres_pipeline.stage_events manual__2025-07-25T18:12:48.278884+00:00 [queued]>
[2025-07-26T01:29:23.049+0700] {taskinstance.py:2076} INFO - Dependencies all met for dep_context=requeueable deps ti=<TaskInstance: etl_local_postgres_pipeline.stage_events manual__2025-07-25T18:12:48.278884+00:00 [queued]>
[2025-07-26T01:29:23.050+0700] {taskinstance.py:2306} INFO - Starting attempt 4 of 4
[2025-07-26T01:29:23.354+0700] {taskinstance.py:2330} INFO - Executing <Task(PythonOperator): stage_events> on 2025-07-25 18:12:48.278884+00:00
[2025-07-26T01:29:23.360+0700] {standard_task_runner.py:90} INFO - Running: ['airflow', 'tasks', 'run', 'etl_local_postgres_pipeline', 'stage_events', 'manual__2025-07-25T18:12:48.278884+00:00', '--job-id', '243', '--raw', '--subdir', 'DAGS_FOLDER/etl_pipeline_pjt.py', '--cfg-path', '/tmp/tmpewmdccf3']
[2025-07-26T01:29:23.362+0700] {standard_task_runner.py:91} INFO - Job 243: Subtask stage_events
[2025-07-26T01:29:23.361+0700] {logging_mixin.py:188} WARNING - /home/ngtph/airflow/airflow_venv/lib/python3.12/site-packages/airflow/task/task_runner/standard_task_runner.py:61 DeprecationWarning: This process (pid=4288) is multi-threaded, use of fork() may lead to deadlocks in the child.
[2025-07-26T01:29:23.362+0700] {standard_task_runner.py:63} INFO - Started process 4291 to run task
[2025-07-26T01:29:25.750+0700] {task_command.py:426} INFO - Running <TaskInstance: etl_local_postgres_pipeline.stage_events manual__2025-07-25T18:12:48.278884+00:00 [running]> on host DESKTOP-9M5T9P5.localdomain
[2025-07-26T01:29:30.498+0700] {taskinstance.py:2648} INFO - Exporting env vars: AIRFLOW_CTX_DAG_OWNER='phuongnt226' AIRFLOW_CTX_DAG_ID='etl_local_postgres_pipeline' AIRFLOW_CTX_TASK_ID='stage_events' AIRFLOW_CTX_EXECUTION_DATE='2025-07-25T18:12:48.278884+00:00' AIRFLOW_CTX_TRY_NUMBER='4' AIRFLOW_CTX_DAG_RUN_ID='manual__2025-07-25T18:12:48.278884+00:00'
[2025-07-26T01:29:30.499+0700] {taskinstance.py:430} INFO - ::endgroup::
[2025-07-26T01:29:31.295+0700] {base.py:84} INFO - Using connection ID 'postgres_id' for task execution.
[2025-07-26T01:29:31.929+0700] {logging_mixin.py:188} INFO - Found 30 event files.
[2025-07-26T01:29:39.829+0700] {taskinstance.py:441} INFO - ::group::Post task execution logs
[2025-07-26T01:29:39.830+0700] {taskinstance.py:2905} ERROR - Task failed with exception
Traceback (most recent call last):
  File "/home/ngtph/airflow/airflow_venv/lib/python3.12/site-packages/airflow/models/taskinstance.py", line 465, in _execute_task
    result = _execute_callable(context=context, **execute_callable_kwargs)
             ^^^^^^^^^^^^^^^^^^^^^^^^^^^^^^^^^^^^^^^^^^^^^^^^^^^^^^^^^^^^^
  File "/home/ngtph/airflow/airflow_venv/lib/python3.12/site-packages/airflow/models/taskinstance.py", line 432, in _execute_callable
    return execute_callable(context=context, **execute_callable_kwargs)
           ^^^^^^^^^^^^^^^^^^^^^^^^^^^^^^^^^^^^^^^^^^^^^^^^^^^^^^^^^^^^
  File "/home/ngtph/airflow/airflow_venv/lib/python3.12/site-packages/airflow/models/baseoperator.py", line 400, in wrapper
    return func(self, *args, **kwargs)
           ^^^^^^^^^^^^^^^^^^^^^^^^^^^
  File "/home/ngtph/airflow/airflow_venv/lib/python3.12/site-packages/airflow/operators/python.py", line 235, in execute
    return_value = self.execute_callable()
                   ^^^^^^^^^^^^^^^^^^^^^^^
  File "/home/ngtph/airflow/airflow_venv/lib/python3.12/site-packages/airflow/operators/python.py", line 252, in execute_callable
    return self.python_callable(*self.op_args, **self.op_kwargs)
           ^^^^^^^^^^^^^^^^^^^^^^^^^^^^^^^^^^^^^^^^^^^^^^^^^^^^^
  File "/home/ngtph/airflow/dags/etl_pipeline_pjt.py", line 106, in stage_events_to_postgres
    cur.execute("""
psycopg2.errors.UndefinedColumn: column "file_path" of relation "loaded_files" does not exist
LINE 2:                 INSERT INTO loaded_files (file_path)
                                                  ^

[2025-07-26T01:29:40.519+0700] {taskinstance.py:1206} INFO - Marking task as FAILED. dag_id=etl_local_postgres_pipeline, task_id=stage_events, run_id=manual__2025-07-25T18:12:48.278884+00:00, execution_date=20250725T181248, start_date=20250725T182922, end_date=20250725T182940
[2025-07-26T01:29:40.909+0700] {standard_task_runner.py:110} ERROR - Failed to execute job 243 for task stage_events (column "file_path" of relation "loaded_files" does not exist
LINE 2:                 INSERT INTO loaded_files (file_path)
                                                  ^
; 4291)
[2025-07-26T01:29:40.949+0700] {local_task_job_runner.py:240} INFO - Task exited with return code 1
[2025-07-26T01:29:42.142+0700] {taskinstance.py:3498} INFO - 0 downstream tasks scheduled from follow-on schedule check
[2025-07-26T01:29:42.341+0700] {local_task_job_runner.py:222} INFO - ::endgroup::
