[2025-07-26T01:07:18.848+0700] {local_task_job_runner.py:120} INFO - ::group::Pre task execution logs
[2025-07-26T01:07:19.769+0700] {taskinstance.py:2076} INFO - Dependencies all met for dep_context=non-requeueable deps ti=<TaskInstance: etl_local_postgres_pipeline.stage_events scheduled__2025-07-25T17:00:00+00:00 [queued]>
[2025-07-26T01:07:20.026+0700] {taskinstance.py:2076} INFO - Dependencies all met for dep_context=requeueable deps ti=<TaskInstance: etl_local_postgres_pipeline.stage_events scheduled__2025-07-25T17:00:00+00:00 [queued]>
[2025-07-26T01:07:20.027+0700] {taskinstance.py:2306} INFO - Starting attempt 7 of 8
[2025-07-26T01:07:20.367+0700] {taskinstance.py:2330} INFO - Executing <Task(PythonOperator): stage_events> on 2025-07-25 17:00:00+00:00
[2025-07-26T01:07:20.383+0700] {logging_mixin.py:188} WARNING - /home/ngtph/airflow/airflow_venv/lib/python3.12/site-packages/airflow/task/task_runner/standard_task_runner.py:61 DeprecationWarning: This process (pid=3431) is multi-threaded, use of fork() may lead to deadlocks in the child.
[2025-07-26T01:07:20.381+0700] {standard_task_runner.py:90} INFO - Running: ['airflow', 'tasks', 'run', 'etl_local_postgres_pipeline', 'stage_events', 'scheduled__2025-07-25T17:00:00+00:00', '--job-id', '225', '--raw', '--subdir', 'DAGS_FOLDER/etl_pipeline_pjt.py', '--cfg-path', '/tmp/tmpt_jf5a69']
[2025-07-26T01:07:20.383+0700] {standard_task_runner.py:63} INFO - Started process 3432 to run task
[2025-07-26T01:07:20.383+0700] {standard_task_runner.py:91} INFO - Job 225: Subtask stage_events
[2025-07-26T01:07:23.112+0700] {task_command.py:426} INFO - Running <TaskInstance: etl_local_postgres_pipeline.stage_events scheduled__2025-07-25T17:00:00+00:00 [running]> on host DESKTOP-9M5T9P5.localdomain
[2025-07-26T01:07:28.325+0700] {taskinstance.py:2648} INFO - Exporting env vars: AIRFLOW_CTX_DAG_OWNER='phuongnt226' AIRFLOW_CTX_DAG_ID='etl_local_postgres_pipeline' AIRFLOW_CTX_TASK_ID='stage_events' AIRFLOW_CTX_EXECUTION_DATE='2025-07-25T17:00:00+00:00' AIRFLOW_CTX_TRY_NUMBER='7' AIRFLOW_CTX_DAG_RUN_ID='scheduled__2025-07-25T17:00:00+00:00'
[2025-07-26T01:07:28.326+0700] {taskinstance.py:430} INFO - ::endgroup::
[2025-07-26T01:07:29.237+0700] {base.py:84} INFO - Using connection ID 'postgres_id' for task execution.
[2025-07-26T01:07:29.943+0700] {logging_mixin.py:188} INFO - Found 30 event files.
[2025-07-26T01:07:41.449+0700] {taskinstance.py:441} INFO - ::group::Post task execution logs
[2025-07-26T01:07:41.450+0700] {taskinstance.py:2905} ERROR - Task failed with exception
Traceback (most recent call last):
  File "/home/ngtph/airflow/airflow_venv/lib/python3.12/site-packages/airflow/models/taskinstance.py", line 465, in _execute_task
    result = _execute_callable(context=context, **execute_callable_kwargs)
             ^^^^^^^^^^^^^^^^^^^^^^^^^^^^^^^^^^^^^^^^^^^^^^^^^^^^^^^^^^^^^
  File "/home/ngtph/airflow/airflow_venv/lib/python3.12/site-packages/airflow/models/taskinstance.py", line 432, in _execute_callable
    return execute_callable(context=context, **execute_callable_kwargs)
           ^^^^^^^^^^^^^^^^^^^^^^^^^^^^^^^^^^^^^^^^^^^^^^^^^^^^^^^^^^^^
  File "/home/ngtph/airflow/airflow_venv/lib/python3.12/site-packages/airflow/models/baseoperator.py", line 400, in wrapper
    return func(self, *args, **kwargs)
           ^^^^^^^^^^^^^^^^^^^^^^^^^^^
  File "/home/ngtph/airflow/airflow_venv/lib/python3.12/site-packages/airflow/operators/python.py", line 235, in execute
    return_value = self.execute_callable()
                   ^^^^^^^^^^^^^^^^^^^^^^^
  File "/home/ngtph/airflow/airflow_venv/lib/python3.12/site-packages/airflow/operators/python.py", line 252, in execute_callable
    return self.python_callable(*self.op_args, **self.op_kwargs)
           ^^^^^^^^^^^^^^^^^^^^^^^^^^^^^^^^^^^^^^^^^^^^^^^^^^^^^
  File "/home/ngtph/airflow/dags/etl_pipeline_pjt.py", line 106, in stage_events_to_postgres
    cur.execute("""
psycopg2.errors.UndefinedColumn: column "file_path" of relation "loaded_files" does not exist
LINE 2:                 INSERT INTO loaded_files (file_path)
                                                  ^

[2025-07-26T01:07:43.269+0700] {taskinstance.py:1206} INFO - Marking task as UP_FOR_RETRY. dag_id=etl_local_postgres_pipeline, task_id=stage_events, run_id=scheduled__2025-07-25T17:00:00+00:00, execution_date=20250725T170000, start_date=20250725T180719, end_date=20250725T180743
[2025-07-26T01:07:44.060+0700] {standard_task_runner.py:110} ERROR - Failed to execute job 225 for task stage_events (column "file_path" of relation "loaded_files" does not exist
LINE 2:                 INSERT INTO loaded_files (file_path)
                                                  ^
; 3432)
[2025-07-26T01:07:44.085+0700] {local_task_job_runner.py:240} INFO - Task exited with return code 1
[2025-07-26T01:07:44.976+0700] {local_task_job_runner.py:222} INFO - ::endgroup::
